<robot name="rbx1_description">
  <link name="world"/>
  <joint name="fixed" type="fixed">
    <parent link="world"/>
    <child link="base_link"/>
  </joint>
  <link name="base_link">
    <inertial>
      <origin xyz="0.034155 -0.20591 -0.049641" rpy="0 0 0" />
      <mass value="8.0643" />
      <inertia ixx="0.11291" ixy="0.00066071" ixz="-0.00030472"
       iyy="0.089946" iyz="0.011461" izz="0.19187" />
    </inertial>
    <visual>
      <origin xyz="0 0 0" rpy="0 0 0" />
      <geometry>
        <mesh filename="package://rbx1_description/meshes/base_link.STL" />
      </geometry>
      <material name="">
        <color rgba="0.75294 0.75294 0.75294 1" />
      </material>
    </visual>
    <collision>
      <origin xyz="0 0 0" rpy="0 0 0" />
      <geometry>
        <mesh filename="package://rbx1_description/meshes/collision/base_link.STL" />
      </geometry>
    </collision>
  </link>

  <!-- CAMERA -->
  <link name="camera_link">
    <inertial>
      <origin xyz="0 0 0" rpy="0 0 0" />
      <mass value="0.010676" />
      <inertia ixx="0.1" ixy="0.1" ixz="0.1" iyy="0.1" iyz="0.1" izz="0.1" />
    </inertial>
    <collision>
      <origin xyz="0 0 0" rpy="0 0 0"/>
      <geometry>
    <box size="0.05 0.05 0.05"/>
      </geometry>
    </collision>

    <visual>
      <origin xyz="0 0 0" rpy="0 0 0"/>
      <geometry>
    <box size="0.05 0.05 0.05"/>
      </geometry>
      <material name="red"/>
    </visual>
  </link>
  <joint name="camera_joint" type="fixed">
    <axis xyz="0 1 0" />
    <origin xyz="0.6 0.6 0.5" rpy="0 0 -1.95"/>
    <parent link="base_link"/>
    <child link="camera_link"/>
  </joint>

  <!-- SHOULDER -->
  <link name="link_1_shoulder">
    <inertial>
      <origin xyz="4.0186E-05 0.090634 0.00010221" rpy="0 0 0" />
      <mass value="4.2526" />
      <inertia ixx="0.0034071" ixy="8.9041E-06" ixz="1.179E-07"
       iyy="0.018642" iyz="-3.6544E-06" izz="0.021987" />
    </inertial>
    <visual>
      <origin xyz="0 0 0" rpy="0 0 0" />
      <geometry>
        <mesh filename="package://rbx1_description/meshes/link_1_shoulder.STL" />
      </geometry>
      <material name="">
        <color rgba="0.86 0.08 0.23 1" />
      </material>
    </visual>
    <collision>
      <origin xyz="0 0 0" rpy="0 0 0" />
      <geometry>
        <mesh filename="package://rbx1_description/meshes/collision/link_1_shoulder.STL" />
      </geometry>
    </collision>
  </link>
  <joint name="joint_1_base_shoulder" type="revolute">
    <origin xyz="0 -0.2425 0" rpy="1.5708 9.5417E-17 0" />
    <parent link="base_link" />
    <child link="link_1_shoulder" />
    <axis xyz="0 1 0" />
    <limit lower="-1.5707975" upper="1.07993" effort="5" velocity="1" />
    <dynamics damping="0.3" friction="0.2" />
  </joint>
  <transmission name="base_shoulder_transmission">
    <type>transmission_interface/SimpleTransmission</type>
    <actuator name="base_shoulder_motor"></actuator>
    <joint name="joint_1_base_shoulder">
      <hardwareInterface>hardware_interface/PositionJointInterface</hardwareInterface>
    </joint>
  </transmission>

  <!-- ARM -->
  <link name="link_2_arm">
    <inertial>
      <origin xyz="2.2815E-05 0.0017616 -0.080002" rpy="0 0 0" />
      <mass value="1.9323" />
      <inertia ixx="0.012138" ixy="-3.5576E-06" ixz="-9.0632E-06"
       iyy="0.011445" iyz="0.00014273" izz="0.00070271" />
    </inertial>
    <visual>
      <origin xyz="0 0 0" rpy="0 0 0" />
      <geometry>
        <mesh filename="package://rbx1_description/meshes/link_2_arm.STL" />
      </geometry>
      <material name="">
        <color rgba="0.86 0.08 0.23 1" />
      </material>
    </visual>
    <collision>
      <origin xyz="0 0 0" rpy="0 0 0" />
      <geometry>
        <mesh filename="package://rbx1_description/meshes/collision/link_2_arm.STL" />
      </geometry>
    </collision>
  </link>
  <joint name="joint_2_shoulder_arm" type="revolute">
    <origin xyz="0 0.18264 0" rpy="-3.1416 1.5708 1.5708" />
    <parent link="link_1_shoulder" />
    <child link="link_2_arm" />
    <axis xyz="0 -1 0" />
    <limit lower="-1.5707975" upper="1.5707975" effort="5" velocity="1" />
    <dynamics damping="0.3" friction="0.2" />
  </joint>
  <transmission name="shoulder_arm_transmission">
    <type>transmission_interface/SimpleTransmission</type>
    <actuator name="shoulder_arm_motor"></actuator>
    <joint name="joint_2_shoulder_arm">
      <hardwareInterface>hardware_interface/PositionJointInterface</hardwareInterface>
    </joint>
  </transmission>


  <!-- UPPER FOREARM -->
  <link name="link_3_upper_forearm">
    <inertial>
      <origin xyz="0.05095 -0.00039084 -0.00045591" rpy="0 0 0" />
      <mass value="1.1381" />
      <inertia ixx="0.00023572" ixy="-3.8425E-06" ixz="4.1286E-06"
       iyy="0.00029123" iyz="-1.0387E-07" izz="0.00052457" />
    </inertial>
    <visual>
      <origin xyz="0 0 0" rpy="0 0 0" />
      <geometry>
        <mesh filename="package://rbx1_description/meshes/link_3_upper_forearm.STL" />
      </geometry>
      <material name="">
        <color rgba="0.86 0.08 0.23 1" />
      </material>
    </visual>
    <collision>
      <origin xyz="0 0 0" rpy="0 0 0" />
      <geometry>
        <mesh filename="package://rbx1_description/meshes/collision/link_3_upper_forearm.STL" />
      </geometry>
    </collision>
  </link>
  <joint name="joint_3_arm_upper_forearm" type="revolute">
    <origin xyz="0 0 -0.22112" rpy="-3.1416 1.5708 -3.1416" />
    <parent link="link_2_arm" />
    <child link="link_3_upper_forearm" />
    <axis xyz="0 -1 0" />
    <limit lower="-1.9635" upper="1.9635" effort="5" velocity="1" />
    <dynamics damping="0.3" friction="0.2" />
  </joint>
  <transmission name="arm_upper_forearm_transmission">
    <type>transmission_interface/SimpleTransmission</type>
    <actuator name="arm_upper_forearm_motor"></actuator>
    <joint name="joint_3_arm_upper_forearm">
      <hardwareInterface>hardware_interface/PositionJointInterface</hardwareInterface>
    </joint>
  </transmission>

  
    <!-- FOREARM -->
  <link name="link_4_forearm">
    <inertial>
      <origin xyz="-0.0027417 0.0025097 0.012864" rpy="0 0 0" />
      <mass value="0.62964" />
      <inertia ixx="0.0001717" ixy="1.3446E-06" ixz="8.5164E-06"
       iyy="0.00010506" iyz="5.1412E-05" izz="7.8944E-05" />
    </inertial>
    <visual>
      <!--<origin xyz="0 0 0" rpy="0 0 0" />-->
      <origin xyz="0.003 0 -0.001" rpy="0 0.11 0" />
      <geometry>
        <mesh filename="package://rbx1_description/meshes/link_4_forearm.STL" />
      </geometry>
      <material name="">
        <color rgba="0.86 0.08 0.23 1" />
      </material>
    </visual>
    <collision>
      <!--<origin xyz="0 0 0" rpy="0 0 0" />-->
      <origin xyz="0.003 0 -0.001" rpy="0 0.11 0" />
      <geometry>
        <mesh filename="package://rbx1_description/meshes/collision/link_4_forearm.STL" />
      </geometry>
    </collision>
  </link>
  <joint name="joint_4_upper_forearm_forearm" type="revolute">
    <origin xyz="0.16988 0 0" rpy="3.1416 1.5708   1.5708" />
    <parent link="link_3_upper_forearm" />
    <child link="link_4_forearm" />
    <axis xyz="0.010353 -0.99993 -0.0059382" />
    <limit lower="-3.141595" upper="3.141595" effort="5" velocity="1" />
    <dynamics damping="0.3" friction="0.2" />
  </joint>
  <transmission name="upper_forearm_forearm_transmission">
    <type>transmission_interface/SimpleTransmission</type>
    <actuator name="upper_forearm_forearm_motor"></actuator>
    <joint name="joint_4_upper_forearm_forearm">
      <hardwareInterface>hardware_interface/PositionJointInterface</hardwareInterface>
    </joint>
  </transmission>

  <!-- WRIST -->
  <link name="link_5_wrist">
    <inertial>
      <origin xyz="-0.011366 0.00012239 0.0078967" rpy="0 0 0" />
      <mass value="0.15" />
      <inertia ixx="6.2676E-05" ixy="4.2551E-06" ixz="4.0215E-05"
       iyy="9.7792E-05" iyz="8.5888E-07" izz="9.5807E-05" />
    </inertial>
    <visual>
      <origin xyz="0 0 0" rpy="0 0 0" />
      <geometry>
        <mesh filename="package://rbx1_description/meshes/link_5_wrist.STL" />
      </geometry>
      <material name="">
        <color rgba="0.86 0.08 0.23 1" />
      </material>
    </visual>
    <collision>
      <origin xyz="0 0 0" rpy="0 0 0" />
      <geometry>
        <mesh filename="package://rbx1_description/meshes/collision/link_5_wrist.STL" />
      </geometry>
    </collision>
  </link>
  <joint name="joint_5_forearm_wrist" type="revolute">
    <!--<origin xyz="-0.0021346 0.053041 0.0016936" rpy="-1.5639 -0.091135 -1.0472" />-->
    <origin xyz="0 0.053041 0" rpy="-1.5708 0 -0.9254" />
    <parent link="link_4_forearm" />
    <child link="link_5_wrist" />
    <axis xyz="0 1 0" />
    <limit lower="-1.7952" upper="1.7951" effort="5" velocity="1" />
    <dynamics damping="0.3" friction="0.2" />
  </joint>
  <transmission name="forearm_wrist_transmission">
    <type>transmission_interface/SimpleTransmission</type>
    <actuator name="forearm_wrist_motor"></actuator>
    <joint name="joint_5_forearm_wrist">
      <hardwareInterface>hardware_interface/PositionJointInterface</hardwareInterface>
    </joint>
  </transmission>

  <!-- HAND -->
  <link name="link_6_hand">
    <inertial>
      <origin xyz="-0.011366 0.00012239 0.0078967" rpy="0 0 0" />
      <mass value="0.04"/>
      <inertia ixx="1.0" ixy="0.0" ixz="0.0"
        iyy="1.0" iyz="0.0" izz="1.0" />
    </inertial>
    <visual>
      <origin xyz="0 0 0" rpy="0 0 0" />
      <geometry>
        <mesh filename="package://rbx1_description/meshes/link_6_hand.STL" />
      </geometry>
      <material name="">
        <color rgba="0.86 0.08 0.23 1" />
      </material>
    </visual>
    <collision>
      <origin xyz="0 0 0" rpy="0 0 0" />
      <geometry>
        <mesh filename="package://rbx1_description/meshes/collision/link_6_hand.STL" />
      </geometry>
    </collision>
  </link>
  <joint name="joint_6_wrist_hand" type="revolute">
    <origin xyz="-0.034 0.0 0.024" rpy="0 0.645772 0" />
    <parent link="link_5_wrist" />
    <child link="link_6_hand" />
    <axis xyz="1 0 0" />
    <limit lower="-3.141595" upper="3.141595" effort="5" velocity="1" />
  </joint>
 <transmission name="wrist_hand_transmission">
    <type>transmission_interface/SimpleTransmission</type>
    <actuator name="wrist_hand_motor"></actuator>
    <joint name="joint_6_wrist_hand">
      <hardwareInterface>hardware_interface/PositionJointInterface</hardwareInterface>
    </joint>
  </transmission>

  <!-- GRIPPER SERVO -->
   <link name="gripper_servo_gear">
    <inertial>
      <origin xyz="0 0 0" rpy="0 0 0" />
      <mass value="0.0048997" />
      <inertia ixx="0.1" ixy="0.1" ixz="0.1" iyy="0.1" iyz="0.1" izz="0.1" />
    </inertial>
    <visual>
      <origin xyz="0 0 0" rpy="0 0 0" />
      <geometry>
        <mesh filename="package://rbx1_description/meshes/gripper_servo_gear.STL" />
      </geometry>
      <material name="">
        <color rgba="0.9098 0.44314 0.031373 1" />
      </material>
    </visual>
    <collision>
      <origin xyz="0 0 0" rpy="0 0 0" />
      <geometry>
        <mesh filename="package://rbx1_description/meshes/collision/gripper_servo_gear.STL" />
      </geometry>
    </collision>
  </link>
 <joint name="gripper_servo_gear_joint" type="revolute">
    <origin xyz="-0.024077 0.014019 0.003057" rpy="1.5708 0.0 -1.5708" />
    <parent link="link_6_hand" />
    <child link="gripper_servo_gear" />
    <axis xyz="0 1 0" />
    <limit lower="0" upper="1.5707" effort="5" velocity="1" />
    <dynamics damping="0.3" friction="0.2" />
  </joint>
  <transmission name="gripper_servo_gear_transmission">
    <type>transmission_interface/SimpleTransmission</type>
    <actuator name="gripper_servo_gear_motor"></actuator>
    <joint name="gripper_servo_gear_joint">
      <hardwareInterface>hardware_interface/PositionJointInterface</hardwareInterface>
    </joint>
  </transmission>

  <link name="tip_gripper_servo">
    <inertial>
      <origin xyz="0 0 0" rpy="0 0 0" />
      <mass value="0.010676" />
      <inertia ixx="0.1" ixy="0.1" ixz="0.1" iyy="0.1" iyz="0.1" izz="0.1" />
    </inertial>
    <visual>
      <origin xyz="0 0 0" rpy="0 0 0" />
      <geometry>
        <mesh filename="package://rbx1_description/meshes/tip_gripper_servo.STL" />
      </geometry>
      <material name="">
        <color rgba="0.6 1 0.27843 1" />
      </material>
    </visual>
    <collision>
      <origin xyz="0 0 0" rpy="0 0 0" />
      <geometry>
        <mesh filename="package://rbx1_description/meshes/collision/tip_gripper_servo.STL" />
      </geometry>
    </collision>
  </link>
  <joint name="tip_gripper_servo_joint" type="revolute">
    <origin xyz="-0.039906 -0.004 -0.0027473" rpy="-3.1416 -1.5569 -2.0392E-12" />
    <parent link="gripper_servo_gear" />
    <child link="tip_gripper_servo" />
    <axis xyz="0 1 0" />
    <limit lower="0" upper="1.3" effort="5" velocity="1" />
    <mimic joint="gripper_servo_gear_joint" multiplier="1" offset="0"/>
  </joint>
  
    <link name="pivot_arm_gripper_servo">
    <inertial>
      <origin xyz="0 0 0" rpy="0 0 0" />
      <mass value="0.0018597" />
      <inertia ixx="0.1" ixy="0.1" ixz="0.1" iyy="0.1" iyz="0.1" izz="0.1" />
    </inertial>
    <visual>
      <origin xyz="0 0 0" rpy="0 0 0" />
      <geometry>
        <mesh filename="package://rbx1_description/meshes/pivot_arm_gripper_servo.STL" />
      </geometry>
      <material name="">
        <color rgba="0.792156862745098 0.819607843137255 0.933333333333333 1" />
      </material>
    </visual>
    <collision>
      <origin xyz="0 0 0" rpy="0 0 0" />
      <geometry>
        <mesh filename="package://rbx1_description/meshes/collision/pivot_arm_gripper_servo.STL" />
      </geometry>
    </collision>
  </link>
  <joint name="pivot_arm_gripper_servo_joint" type="revolute">
    <origin xyz="-0.044253 0.007042 -0.000282" rpy="1.5708 0.0 -1.6308" />
    <parent link="link_6_hand" />
    <child link="pivot_arm_gripper_servo" />
    <axis xyz="0 1 0" />
    <limit lower="-1" upper="1" effort="5" velocity="1" />
    <mimic joint="gripper_servo_gear_joint" multiplier="1" offset="0"/> 
  </joint>

  <!-- GRIPPER IDOL -->
  <link name="gripper_idol_gear">
    <inertial>
      <origin xyz="0 0 0" rpy="0 0 0" />
      <mass value="0.0051273" />
      <inertia ixx="0.1" ixy="0.1" ixz="0.1" iyy="0.1" iyz="0.1" izz="0.1" />
    </inertial>
    <visual>
      <origin xyz="0 0 0" rpy="0 0 0" />
      <geometry>
        <mesh filename="package://rbx1_description/meshes/gripper_idol_gear.STL" />
      </geometry>
      <material name="">
        <color rgba="0.058824 0.64706 1 1" />
      </material>
    </visual>
    <collision>
      <origin xyz="0 0 0" rpy="0 0 0" />
      <geometry>
        <mesh filename="package://rbx1_description/meshes/collision/gripper_idol_gear.STL" />
      </geometry>
    </collision>
  </link>
  <joint name="gripper_idol_gear_joint" type="revolute">
    <origin xyz="-0.024233 -0.013715 -0.00052" rpy="4.71239 0.0 1.5708" />
    <parent link="link_6_hand" />
    <child link="gripper_idol_gear" />
    <axis xyz="0 1 0" />
    <dynamics damping="0.3" friction="0.2" />
    <limit lower="0" upper="1.5707" effort="5" velocity="1" />
  </joint>
   <transmission name="gripper_idol_gear_transmission">
    <type>transmission_interface/SimpleTransmission</type>
    <actuator name="gripper_idol_gear_motor"></actuator>
    <joint name="gripper_idol_gear_joint">
      <hardwareInterface>hardware_interface/PositionJointInterface</hardwareInterface>
    </joint>
  </transmission>

  <link name="tip_gripper_idol">
    <inertial>
      <origin xyz="0 0 0" rpy="0 0 0" />
      <mass value="0.010676" />
      <inertia ixx="0.1" ixy="0.1" ixz="0.1" iyy="0.1" iyz="0.1" izz="0.1" />
    </inertial>
    <visual>
      <origin xyz="0 0 0" rpy="0 0 0" />
      <geometry>
        <mesh filename="package://rbx1_description/meshes/tip_gripper_idol.STL" />
      </geometry>
      <material name="">
        <color rgba="0.79216 0.81961 0.93333 1" />
      </material>
    </visual>
    <collision>
      <origin xyz="0 0 0" rpy="0 0 0" />
      <geometry>
        <mesh filename="package://rbx1_description/meshes/collision/tip_gripper_idol.STL" />
      </geometry>
    </collision>
  </link>
  <joint name="tip_gripper_idol_joint" type="revolute">
    <origin xyz="-0.040206 0 -0.001701" rpy="0.0 -0.5236 -3.1416" />
    <parent link="gripper_idol_gear" />
    <child link="tip_gripper_idol" />
    <axis xyz="0 1 0" />
    <limit lower="0" upper="1.4" effort="5" velocity="1" />
    <mimic joint="gripper_idol_gear_joint" multiplier="1" offset="0"/>
  </joint>

  <link name="pivot_arm_gripper_idol">
    <inertial>
      <origin xyz="0 0 0" rpy="0 0 0" />
      <mass value="0.0018597" />
      <inertia ixx="0.1" ixy="0.1" ixz="0.1" iyy="0.1" iyz="0.1" izz="0.1" />
    </inertial>
    <visual>
      <origin xyz="0 0 0" rpy="0 0 0" />
      <geometry>
        <mesh filename="package://rbx1_description/meshes/pivot_arm_gripper_idol.STL" />
      </geometry>
      <material name="">
        <color rgba="0.79216 0.81961 0.93333 1" />
      </material>
    </visual>
    <collision>
      <origin xyz="0 0 0" rpy="0 0 0" />
      <geometry>
        <mesh filename="package://rbx1_description/meshes/collision/pivot_arm_gripper_idol.STL" />
      </geometry>
    </collision>
  </link>
  <joint name="pivot_arm_gripper_idol_joint" type="revolute">
    <origin xyz="-0.044291 -0.007028 -0.000002" rpy="4.71239 0.0 -1.5708" />
    <parent link="link_6_hand" />
    <child link="pivot_arm_gripper_idol" />
    <axis xyz="0 1 0" />
    <limit lower="-1.5" upper="0" effort="5" velocity="1" />
    <mimic joint="gripper_idol_gear_joint" multiplier="1" offset="0"/> 
  </joint>

  <!-- Makes the arm collide with the platform mesh-->
  <gazebo reference="base_link">
    <selfCollide>true</selfCollide>
  </gazebo>
  <gazebo reference="link_1_shoulder">
    <material>Gazebo/Red</material>
  </gazebo>
  <gazebo reference="link_2_arm">
    <material>Gazebo/Red</material>
  </gazebo>
  <gazebo reference="link_3_upper_forearm">
    <material>Gazebo/Red</material>
  </gazebo>
  <gazebo reference="link_4_forearm">
    <material>Gazebo/Red</material>
  </gazebo>

  <gazebo reference="link_5_wrist">
    <material>Gazebo/Red</material>
  </gazebo>

  <gazebo reference="link_6_hand">
    <material>Gazebo/Red</material>
  </gazebo>
  <!-- Mimic tag does not work with gazebo. Use a mimic joint plugin instead-->
   <gazebo>
    <plugin name="gazebo_ros_control" filename="libgazebo_ros_control.so">
      <robotNamespace>/</robotNamespace>
    </plugin>
    <plugin name="MimicJointPlugin" filename="libroboticsgroup_gazebo_mimic_joint_plugin.so">
      <joint>gripper_idol_gear_joint</joint>
      <mimicJoint>pivot_arm_gripper_idol_joint</mimicJoint>
      <multiplier>1</multiplier>
      <offset>0</offset>
    </plugin>
    <plugin name="MimicJointPlugin" filename="libroboticsgroup_gazebo_mimic_joint_plugin.so">
      <joint>gripper_servo_gear_joint</joint>
      <mimicJoint>pivot_arm_gripper_servo_joint</mimicJoint>
      <multiplier>1</multiplier>
      <offset>0</offset>
    </plugin>
    <plugin name="MimicJointPlugin" filename="libroboticsgroup_gazebo_mimic_joint_plugin.so">
      <joint>gripper_servo_gear_joint</joint>
      <mimicJoint>tip_gripper_servo_joint</mimicJoint>
      <multiplier>1</multiplier>
      <offset>0</offset>
    </plugin>
    <plugin name="MimicJointPlugin" filename="libroboticsgroup_gazebo_mimic_joint_plugin.so">
      <joint>gripper_idol_gear_joint</joint>
      <mimicJoint>tip_gripper_idol_joint</mimicJoint>
      <multiplier>1</multiplier>
      <offset>0</offset>
    </plugin>
  </gazebo>

  <gazebo reference="camera_link">
    <sensor type="camera" name="overview_camera">
      <update_rate>15.0</update_rate>
      <camera name="head">
        <horizontal_fov>1.3962634</horizontal_fov>
        <image>
          <width>640</width>
          <height>480</height>
          <format>R8G8B8</format>
        </image>
        <clip>
          <near>0.02</near>
          <far>300</far>
        </clip>
        <noise>
          <type>gaussian</type>
          <mean>0.0</mean>
          <stddev>0.007</stddev>
        </noise>
      </camera>
      <plugin name="camera_controller" filename="libgazebo_ros_camera.so">
        <alwaysOn>true</alwaysOn>
        <updateRate>0.0</updateRate>
        <visualize>1</visualize>
        <cameraName>overview_camera</cameraName>
        <imageTopicName>image_raw</imageTopicName>
        <cameraInfoTopicName>camera_info</cameraInfoTopicName>
        <frameName>camera_link</frameName>
        <hackBaseline>0.07</hackBaseline>
        <distortionK1>0.0</distortionK1>
        <distortionK2>0.0</distortionK2>
        <distortionK3>0.0</distortionK3>
        <distortionT1>0.0</distortionT1>
        <distortionT2>0.0</distortionT2>
      </plugin>
    </sensor>
  </gazebo>
</robot>
